<mujoco>
	<option>
		<flag sensornoise="enable"  contact="enable"/>
	</option>
	<worldbody>
    <light diffuse=".5 .5 .5" pos="0 0 5" dir="0 0 -1"/>
		<geom type="plane" size="50 50 0.1" rgba="0.1 0.9 0.7 1"/>
		<body pos="0 0 2" euler="90 0 0">
		<geom type="sphere" pos="0 0 -0.5" size="0.075" rgba="1 1 1 0.5"/>
		<geom type="sphere" pos="0 0 0.5" size="0.075" rgba="1 1 1 0.5"/>
			<joint name="pin" type="hinge" pos="0 0 0.5" axis="0 1 0" damping="5.0"/>
			<geom type="cylinder" size=".05 .5" rgba="0 .2 0.9 1" />
			<inertial mass="0.1" pos="0 0 0.25" diaginertia="0.1 0.1 0.1"/>
			<body pos="0 0 0" euler="0 0 0">
				<joint name="pin2" type="hinge" pos="0 0 -0.5" axis="0 1 0" damping="5.0"/>
				<geom type="cylinder" size=".05 .5" rgba="0.9 0.5 0 1" />
				<inertial mass="0.2" pos="0 0 0.25" diaginertia="0.1 0.1 0.1"/>
			</body>
		</body>
	</worldbody>
<!--	<actuator>-->
<!--		 <motor name="torque1" joint="pin" gear="1" ctrlrange="-1 1" ctrllimited="true"/>-->
<!--		<motor name="torque" joint="pin2" gear="1" ctrlrange="-1 1" ctrllimited="true"/>-->
<!--	</actuator>-->
	<actuator>
        <position name="torque1" joint="pin" kp="100" gear="1" ctrlrange="-3.14 3.14" ctrllimited="true"/>
        <position name="torque" joint="pin2" kp="100" gear="1" ctrlrange="-3.14 3.14" ctrllimited="true"/>
    </actuator>
	<sensor>
		<jointpos joint="pin" noise="0"/>
		<jointpos joint="pin2" noise="0"/>
		<jointvel joint="pin" noise="0"/>
		<jointvel joint="pin2" noise="0"/>
	</sensor>
</mujoco>
